<?xml version="1.0" encoding="UTF-8"?>
<!-- Generated by org.testng.reporters.JUnitXMLReporter -->
<testsuite ignored="0" hostname="xjtdeMBP" failures="2" tests="3" name="reportdemo2" time="0.299" errors="0" timestamp="10 10月 2019 01:42:21 GMT">
  <testcase classname="cn.skio.apis.extentReport.TestReportDemo" name="test1" time="0.027">
    <failure type="java.lang.AssertionError" message="expected [2] but found [1]">
        <![CDATA[java.lang.AssertionError: expected [2] but found [1]
	at cn.skio.apis.extentReport.TestReportDemo.test1(ReportTest.java:16)
... Removed 30 stack frames]]>
    </failure>
  </testcase> <!-- test1 -->
  <testcase classname="cn.skio.apis.extentReport.TestReportDemo" name="test2" time="0.0"/>
  <testcase classname="cn.skio.apis.extentReport.TestReportDemo" name="reportTest" time="0.001">
    <failure type="java.lang.RuntimeException" message="这是自己抛出的运行异常">
        <![CDATA[java.lang.RuntimeException: 这是自己抛出的运行异常
	at cn.skio.apis.extentReport.TestReportDemo.reportTest(ReportTest.java:27)
... Removed 24 stack frames]]>
    </failure>
  </testcase> <!-- reportTest -->
</testsuite> <!-- reportdemo2 -->
